Workbook
Name From_20: [1]Ref!$P$2:$P$5
Name KPB_DUO_sizes: [1]Ref!$M$2:$M$6
Name KPB_sizes: [1]Ref!$K$2:$K$10
Name KVBF: [1]Ref!$Q$2
Name KVBF_sizes: [1]Ref!$L$2:$L$10
Name Up_to_18: [1]Ref!$O$2:$O$5

Sheet COST
Q2: =Q883 -> 3211396.3 | S2: =S883 -> 3211396.3 | T2: =T883 -> 170000 | U2: =U883 -> 3381396.3 | Z2: =Z883 -> 4332914.7 | AC2: =AC883 -> 6500000 | AP2: 0
B3: SN | C3: Location | D3: Fan Ref. (SN) | E3: Origin | F3: Fan Type | G3: Speed | H3: Smoke Rating | I3: Article No. | J3: Item Code (Model) | K3: Flow l/s | L3: ESP Pa | M3: Globle Price | N3: EX Price € | O3: Discount | P3: Qty. | Q3: Basic T EX Price € | R3: Discount on Basic T EX Price € | S3: Final T EX Price € | T3: Shipping | U3: CIF | V3: Customs | W3: VAT | X3: COST FACTORS | Y3: Currency rate | Z3: Dry DDP Cost € | AA3: MG | AB3: Unit Price € | AC3: Total Price € | AK3: 0 | AL3: China | AM3: Axial Inline | AN3: Variable | AO3: 300°C/2Hr | AP3: 0.05
A4: =VALUE(RIGHT(B4,LEN(B4)-2)) -> 1 | B4: F-01 | D4: FAF-A29-B02-01 | E4: Germany | F4: Axial Inline | G4: Single | H4: Ambient | I4: CAP071140001G | J4: AXC 710-9/20°-4-P (350) (3 kW) S IE3 | K4: 3560 | L4: 375 | M4: =IF(ISERROR(VLOOKUP(J4,'Germany price'!$B$1:$G$99001,6,0))," ",VLOOKUP(J4,'Germany price'!$B$1:$G$99001,6,0)) | N4: 2515 | O4: 0.58 | P4: 2 | Q4: =N4*P4*(1-O4) -> 2112.6 | R4: 0 | S4: =Q4*(1-R4) -> 2112.6 | T4: =(Q4*AE4)/AF4 -> 111.8336 | U4: =T4+S4 -> 2224.4336 | V4: 0 | W4: =1.14 -> 1.14 | X4: =1.05*1.07 -> 1.1235 | Y4: 1 | Z4: =U4*X4*Y4*W4*(1+V4) -> 2849.0323 | AA4: =(6500000/Z2)-1 -> 0.50014493 | AB4: =AC4/P4 -> 2136.9807 | AC4: =U4*X4*(1+AA4)*Y4*W4*(1+V4) -> 4273.9614 | AE4: 170000 | AF4: =Q883 -> 3211396.3 | AK4: 0.05 | AL4: Sweden | AM4: Centrifugal Inline | AN4: Single | AO4: 400°C/2Hr | AP4: 0.08
A5: =VALUE(RIGHT(B5,LEN(B5)-2)) -> 2 | B5: F-02 | D5: FAF-A29-B02-02 | E5: Germany | F5: Centrifugal Inline | G5: Single | H5: Ambient | I5: 235403 | J5: MUB 042 400EV Multibox | K5: 580 | L5: 250 | M5: =IF(ISERROR(VLOOKUP(J5,'Germany price'!$B$1:$G$99001,6,0))," ",VLOOKUP(J5,'Germany price'!$B$1:$G$99001,6,0)) -> 1199 | N5: 1199 | O5: 0.58 | P5: 1 | Q5: =N5*P5*(1-O5) -> 503.58 | R5: =R4 -> 0 | S5: =Q5*(1-R5) -> 503.58 | T5: =(Q5*AE5)/AF5 -> 26.65775 | U5: =T5+S5 -> 530.23775 | V5: 0 | W5: =1.14 -> 1.14 | X5: =X4 -> 1.1235 | Y5: =Y4 -> 1 | Z5: =U5*X5*Y5*W5*(1+V5) -> 679.12321 | AA5: =AA4 -> 0.50014493 | AB5: =AC5/P5 -> 1018.7832 | AC5: =U5*X5*(1+AA5)*Y5*W5*(1+V5) -> 1018.7832 | AE5: =AE4 -> 170000 | AF5: =AF4 -> 3211396.3 | AK5: 0.1 | AL5: Germany | AM5: Inline Fan | AN5: Double | AO5: Ambient | AP5: 0.1
A6: =VALUE(RIGHT(B6,LEN(B6)-2)) -> 3 | B6: F-03 | D6: FAF-A30-B02-01 | E6: Sweden | F6: Inline Fan | G6: Single | H6: Ambient | I6: 93097 | J6: KT 60-30-4 | K6: 855 | L6: 250 | M6: =IF(ISERROR(VLOOKUP(J6,'Germany price'!$B$1:$G$99001,6,0))," ",VLOOKUP(J6,'Germany price'!$B$1:$G$99001,6,0)) -> 1182 | N6: 1182 | O6: 0.58 | P6: 1 | Q6: =N6*P6*(1-O6) -> 496.44 | R6: =R5 -> 0 | S6: =Q6*(1-R6) -> 496.44 | T6: =(Q6*AE6)/AF6 -> 26.279783 | U6: =T6+S6 -> 522.71978 | V6: 0 | W6: =1.14 -> 1.14 | X6: =X5 -> 1.1235 | Y6: =Y5 -> 1 | Z6: =U6*X6*Y6*W6*(1+V6) -> 669.49427 | AA6: =AA5 -> 0.50014493 | AB6: =AC6/P6 -> 1004.3384 | AC6: =U6*X6*(1+AA6)*Y6*W6*(1+V6) -> 1004.3384 | AE6: =AE5 -> 170000 | AF6: =AF5 -> 3211396.3 | AK6: 0.6 | AL6: Malaysia | AM6: Wall Mounted | AO6: Explosion | AP6: 0.11
A7: =VALUE(RIGHT(B7,LEN(B7)-2)) -> 4 | B7: F-04 | D7: FAF-A35-B02-01 | E7: Germany | F7: Axial Inline | G7: Single | H7: Ambient | I7: CAP040120001F | J7: AXC 400-6/31°-2-P (160) (2.2 kW) S IE3 C | K7: 2240 | L7: 250 | M7: =IF(ISERROR(VLOOKUP(J7,'Germany price'!$B$1:$G$99001,6,0))," ",VLOOKUP(J7,'Germany price'!$B$1:$G$99001,6,0)) | N7: 1499 | O7: 0.58 | P7: 2 | Q7: =N7*P7*(1-O7) -> 1259.16 | R7: =R6 -> 0 | S7: =Q7*(1-R7) -> 1259.16 | T7: =(Q7*AE7)/AF7 -> 66.655491 | U7: =T7+S7 -> 1325.8155 | V7: 0 | W7: =1.14 -> 1.14 | X7: =X6 -> 1.1235 | Y7: =Y6 -> 1 | Z7: =U7*X7*Y7*W7*(1+V7) -> 1698.0912 | AA7: =AA6 -> 0.50014493 | AB7: =AC7/P7 -> 1273.6915 | AC7: =U7*X7*(1+AA7)*Y7*W7*(1+V7) -> 2547.3829 | AE7: =AE6 -> 170000 | AF7: =AF6 -> 3211396.3 | AL7: Italy | AM7: Fan Section | AO7: 120°C | AP7: 0.12
A8: =VALUE(RIGHT(B8,LEN(B8)-2)) -> 5 | B8: F-05 | D8: FAF-A35-B02-02 | E8: Germany | F8: Centrifugal Fan | G8: Single | H8: Ambient | I8: 334079 | J8: PRF 355D4 | K8: 1125 | L8: 250 | M8: =IF(ISERROR(VLOOKUP(J8,'Germany price'!$B$1:$G$99001,6,0))," ",VLOOKUP(J8,'Germany price'!$B$1:$G$99001,6,0)) -> 6324 | N8: 6324 | O8: 0.58 | P8: 1 | Q8: =N8*P8*(1-O8) -> 2656.08 | R8: =R7 -> 0 | S8: =Q8*(1-R8) -> 2656.08 | T8: =(Q8*AE8)/AF8 -> 140.60351 | U8: =T8+S8 -> 2796.6835 | V8: 0 | W8: =1.14 -> 1.14 | X8: =X7 -> 1.1235 | Y8: =Y7 -> 1 | Z8: =U8*X8*Y8*W8*(1+V8) -> 3581.9643 | AA8: =AA7 -> 0.50014493 | AB8: =AC8/P8 -> 5373.4656 | AC8: =U8*X8*(1+AA8)*Y8*W8*(1+V8) -> 5373.4656 | AE8: =AE7 -> 170000 | AF8: =AF7 -> 3211396.3 | AL8: UAE | AM8: Axial Roof Top | AP8: 0.13
A9: =VALUE(RIGHT(B9,LEN(B9)-2)) -> 6 | B9: F-06 | D9: FAF-B30-B02-02 | E9: Sweden | F9: Inline Fan | G9: Single | H9: Ambient | I9: 19514 | J9: K 315 L Sileo** | K9: 340 | L9: 125 | M9: =IF(ISERROR(VLOOKUP(J9,'Germany price'!$B$1:$G$99001,6,0))," ",VLOOKUP(J9,'Germany price'!$B$1:$G$99001,6,0)) -> 330 | N9: 330 | O9: 0.58 | P9: 1 | Q9: =N9*P9*(1-O9) -> 138.6 | R9: =R8 -> 0 | S9: =Q9*(1-R9) -> 138.6 | T9: =(Q9*AE9)/AF9 -> 7.3369953 | U9: =T9+S9 -> 145.937 | V9: 0 | W9: =1.14 -> 1.14 | X9: =X8 -> 1.1235 | Y9: =Y8 -> 1 | Z9: =U9*X9*Y9*W9*(1+V9) -> 186.91464 | AA9: =AA8 -> 0.50014493 | AB9: =AC9/P9 -> 280.39906 | AC9: =U9*X9*(1+AA9)*Y9*W9*(1+V9) -> 280.39906 | AE9: =AE8 -> 170000 | AF9: =AF8 -> 3211396.3 | AL9: Slovenia | AM9: Centrifugal Roof Top | AP9: 0.14
A10: =VALUE(RIGHT(B10,LEN(B10)-2)) -> 7 | B10: F-07 | D10: FAF-B35-B02-01 | E10: Sweden | F10: Inline Fan | G10: Single | H10: Ambient | I10: 93098 | J10: KT 60-35-4 | K10: 1025 | L10: 250 | M10: =IF(ISERROR(VLOOKUP(J10,'Germany price'!$B$1:$G$99001,6,0))," ",VLOOKUP(J10,'Germany price'!$B$1:$G$99001,6,0)) -> 1443 | N10: 1443 | O10: 0.58 | P10: 1 | Q10: =N10*P10*(1-O10) -> 606.06 | R10: =R9 -> 0 | S10: =Q10*(1-R10) -> 606.06 | T10: =(Q10*AE10)/AF10 -> 32.08268 | U10: =T10+S10 -> 638.14268 | V10: 0 | W10: =1.14 -> 1.14 | X10: =X9 -> 1.1235 | Y10: =Y9 -> 1 | Z10: =U10*X10*Y10*W10*(1+V10) -> 817.32676 | AA10: =AA9 -> 0.50014493 | AB10: =AC10/P10 -> 1226.1086 | AC10: =U10*X10*(1+AA10)*Y10*W10*(1+V10) -> 1226.1086 | AE10: =AE9 -> 170000 | AF10: =AF9 -> 3211396.3 | AL10: Egypt | AM10: Induction Jet Fan | AP10: 0.15
A11: =VALUE(RIGHT(B11,LEN(B11)-2)) -> 8 | B11: F-08 | D11: FAF-B35-B02-02 | E11: Germany | F11: Axial Inline | G11: Single | H11: Ambient | I11: CAPV080340001H | J11: AXC 800-6/20°-4-PV (350) (4 kW) S IE3 A | K11: 5800 | L11: 375 | M11: =IF(ISERROR(VLOOKUP(J11,'Germany price'!$B$1:$G$99001,6,0))," ",VLOOKUP(J11,'Germany price'!$B$1:$G$99001,6,0)) | N11: 3240 | O11: 0.58 | P11: 2 | Q11: =N11*P11*(1-O11) -> 2721.6 | R11: =R10 -> 0 | S11: =Q11*(1-R11) -> 2721.6 | T11: =(Q11*AE11)/AF11 -> 144.07191 | U11: =T11+S11 -> 2865.6719 | V11: 0 | W11: =1.14 -> 1.14 | X11: =X10 -> 1.1235 | Y11: =Y10 -> 1 | Z11: =U11*X11*Y11*W11*(1+V11) -> 3670.3239 | AA11: =AA10 -> 0.50014493 | AB11: =AC11/P11 -> 2753.0089 | AC11: =U11*X11*(1+AA11)*Y11*W11*(1+V11) -> 5506.0178 | AE11: =AE10 -> 170000 | AF11: =AF10 -> 3211396.3 | AL11: Turkey | AM11: Impulse Jet Fan | AP11: 0.2
A12: =VALUE(RIGHT(B12,LEN(B12)-2)) -> 9 | B12: F-09 | D12: FAF-B35-B02-03 | E12: Germany | F12: Axial Inline | G12: Single | H12: Ambient | I12: CAP045120001F | J12: AXC 450-6/23°-2-P (200) (2.2 kW) S IE3 | K12: 2405 | L12: 375 | M12: =IF(ISERROR(VLOOKUP(J12,'Germany price'!$B$1:$G$99001,6,0))," ",VLOOKUP(J12,'Germany price'!$B$1:$G$99001,6,0)) | N12: 1666 | O12: 0.58 | P12: 1 | Q12: =N12*P12*(1-O12) -> 699.72 | R12: =R11 -> 0 | S12: =Q12*(1-R12) -> 699.72 | T12: =(Q12*AE12)/AF12 -> 37.04071 | U12: =T12+S12 -> 736.76071 | V12: 0 | W12: =1.14 -> 1.14 | X12: =X11 -> 1.1235 | Y12: =Y11 -> 1 | Z12: =U12*X12*Y12*W12*(1+V12) -> 943.63575 | AA12: =AA11 -> 0.50014493 | AB12: =AC12/P12 -> 1415.5904 | AC12: =U12*X12*(1+AA12)*Y12*W12*(1+V12) -> 1415.5904 | AE12: =AE11 -> 170000 | AF12: =AF11 -> 3211396.3 | AM12: Belt Driven Box fan | AP12: 0.25
A13: =VALUE(RIGHT(B13,LEN(B13)-2)) -> 10 | B13: F-10 | D13: FAF-B35-B02-04 | E13: Sweden | F13: Inline Fan | G13: Single | H13: Ambient | I13: 27758 | J13: K 315 M sileo** | K13: 210 | L13: 250 | M13: =IF(ISERROR(VLOOKUP(J13,'Germany price'!$B$1:$G$99001,6,0))," ",VLOOKUP(J13,'Germany price'!$B$1:$G$99001,6,0)) -> 276 | N13: 276 | O13: 0.58 | P13: 1 | Q13: =N13*P13*(1-O13) -> 115.92 | R13: =R12 -> 0 | S13: =Q13*(1-R13) -> 115.92 | T13: =(Q13*AE13)/AF13 -> 6.1363961 | U13: =T13+S13 -> 122.0564 | V13: 0 | W13: =1.14 -> 1.14 | X13: =X12 -> 1.1235 | Y13: =Y12 -> 1 | Z13: =U13*X13*Y13*W13*(1+V13) -> 156.32861 | AA13: =AA12 -> 0.50014493 | AB13: =AC13/P13 -> 234.51557 | AC13: =U13*X13*(1+AA13)*Y13*W13*(1+V13) -> 234.51557 | AE13: =AE12 -> 170000 | AF13: =AF12 -> 3211396.3 | AM13: Centrifugal Box Fan | AP13: 0.3
A14: =VALUE(RIGHT(B14,LEN(B14)-2)) -> 11 | B14: F-11 | D14: FAF-C29-B02-01 | E14: Sweden | F14: Inline Fan | G14: Single | H14: Ambient | I14: 93098 | J14: KT 60-35-4 | K14: 1145 | L14: 250 | M14: =IF(ISERROR(VLOOKUP(J14,'Germany price'!$B$1:$G$99001,6,0))," ",VLOOKUP(J14,'Germany price'!$B$1:$G$99001,6,0)) -> 1443 | N14: 1443 | O14: 0.58 | P14: 1 | Q14: =N14*P14*(1-O14) -> 606.06 | R14: =R13 -> 0 | S14: =Q14*(1-R14) -> 606.06 | T14: =(Q14*AE14)/AF14 -> 32.08268 | U14: =T14+S14 -> 638.14268 | V14: 0 | W14: =1.14 -> 1.14 | X14: =X13 -> 1.1235 | Y14: =Y13 -> 1 | Z14: =U14*X14*Y14*W14*(1+V14) -> 817.32676 | AA14: =AA13 -> 0.50014493 | AB14: =AC14/P14 -> 1226.1086 | AC14: =U14*X14*(1+AA14)*Y14*W14*(1+V14) -> 1226.1086 | AE14: =AE13 -> 170000 | AF14: =AF13 -> 3211396.3 | AM14: Centrifugal Fan | AP14: 0.35
A15: =VALUE(RIGHT(B15,LEN(B15)-2)) -> 12 | B15: F-12 | D15: FAF-C29-B02-02 | E15: Sweden | F15: Inline Fan | G15: Single | H15: Ambient | I15: 93097 | J15: KT 60-30-4 | K15: 725 | L15: 250 | M15: =IF(ISERROR(VLOOKUP(J15,'Germany price'!$B$1:$G$99001,6,0))," ",VLOOKUP(J15,'Germany price'!$B$1:$G$99001,6,0)) -> 1182 | N15: 1182 | O15: 0.58 | P15: 1 | Q15: =N15*P15*(1-O15) -> 496.44 | R15: =R14 -> 0 | S15: =Q15*(1-R15) -> 496.44 | T15: =(Q15*AE15)/AF15 -> 26.279783 | U15: =T15+S15 -> 522.71978 | V15: 0 | W15: =1.14 -> 1.14 | X15: =X14 -> 1.1235 | Y15: =Y14 -> 1 | Z15: =U15*X15*Y15*W15*(1+V15) -> 669.49427 | AA15: =AA14 -> 0.50014493 | AB15: =AC15/P15 -> 1004.3384 | AC15: =U15*X15*(1+AA15)*Y15*W15*(1+V15) -> 1004.3384 | AE15: =AE14 -> 170000 | AF15: =AF14 -> 3211396.3 | AM15: Accessories | AP15: 0.4
A16: =VALUE(RIGHT(B16,LEN(B16)-2)) -> 13 | B16: F-13 | D16: FAF-C29-B02-03 | E16: Germany | F16: Axial Inline | G16: Single | H16: Ambient | I16: CAP080340001H | J16: AXC 800-6/17°-4-P (350) (4 kW) S IE3 | K16: 4450 | L16: 375 | M16: =IF(ISERROR(VLOOKUP(J16,'Germany price'!$B$1:$G$99001,6,0))," ",VLOOKUP(J16,'Germany price'!$B$1:$G$99001,6,0)) | N16: 2721 | O16: 0.58 | P16: 2 | Q16: =N16*P16*(1-O16) -> 2285.64 | R16: =R15 -> 0 | S16: =Q16*(1-R16) -> 2285.64 | T16: =(Q16*AE16)/AF16 -> 120.99372 | U16: =T16+S16 -> 2406.6337 | V16: 0 | W16: =1.14 -> 1.14 | X16: =X15 -> 1.1235 | Y16: =Y15 -> 1 | Z16: =U16*X16*Y16*W16*(1+V16) -> 3082.3924 | AA16: =AA15 -> 0.50014493 | AB16: =AC16/P16 -> 2312.0177 | AC16: =U16*X16*(1+AA16)*Y16*W16*(1+V16) -> 4624.0354 | AE16: =AE15 -> 170000 | AF16: =AF15 -> 3211396.3 | AM16: Planum Fan | AP16: 0.45
A17: =VALUE(RIGHT(B17,LEN(B17)-2)) -> 14 | B17: F-14 | D17: FAF-C29-B02-04 | E17: Germany | F17: Centrifugal Fan | G17: Single | H17: Ambient | I17: 334079 | J17: PRF 355D4 | K17: 785 | L17: 250 | M17: =IF(ISERROR(VLOOKUP(J17,'Germany price'!$B$1:$G$99001,6,0))," ",VLOOKUP(J17,'Germany price'!$B$1:$G$99001,6,0)) -> 6324 | N17: 6324 | O17: 0.58 | P17: 1 | Q17: =N17*P17*(1-O17) -> 2656.08 | R17: =R16 -> 0 | S17: =Q17*(1-R17) -> 2656.08 | T17: =(Q17*AE17)/AF17 -> 140.60351 | U17: =T17+S17 -> 2796.6835 | V17: 0 | W17: =1.14 -> 1.14 | X17: =X16 -> 1.1235 | Y17: =Y16 -> 1 | Z17: =U17*X17*Y17*W17*(1+V17) -> 3581.9643 | AA17: =AA16 -> 0.50014493 | AB17: =AC17/P17 -> 5373.4656 | AC17: =U17*X17*(1+AA17)*Y17*W17*(1+V17) -> 5373.4656 | AE17: =AE16 -> 170000 | AF17: =AF16 -> 3211396.3 | AM17: SISW Fan | AP17: 0.58
A18: =VALUE(RIGHT(B18,LEN(B18)-2)) -> 15 | B18: F-15 | D18: FAF-C35-B02-01 | E18: Sweden | F18: Inline Fan | G18: Single | H18: Ambient | I18: 27758 | J18: K 315 M sileo** | K18: 250 | L18: 125 | M18: =IF(ISERROR(VLOOKUP(J18,'Germany price'!$B$1:$G$99001,6,0))," ",VLOOKUP(J18,'Germany price'!$B$1:$G$99001,6,0)) -> 276 | N18: 276 | O18: 0.58 | P18: 1 | Q18: =N18*P18*(1-O18) -> 115.92 | R18: =R17 -> 0 | S18: =Q18*(1-R18) -> 115.92 | T18: =(Q18*AE18)/AF18 -> 6.1363961 | U18: =T18+S18 -> 122.0564 | V18: 0 | W18: =1.14 -> 1.14 | X18: =X17 -> 1.1235 | Y18: =Y17 -> 1 | Z18: =U18*X18*Y18*W18*(1+V18) -> 156.32861 | AA18: =AA17 -> 0.50014493 | AB18: =AC18/P18 -> 234.51557 | AC18: =U18*X18*(1+AA18)*Y18*W18*(1+V18) -> 234.51557 | AE18: =AE17 -> 170000 | AF18: =AF17 -> 3211396.3 | AM18: Hood Fan
A19: =VALUE(RIGHT(B19,LEN(B19)-2)) -> 16 | B19: F-16 | D19: FAF-C35-B02-03 | E19: Germany | F19: Axial Inline | G19: Single | H19: Ambient | I19: CAP035120001D | J19: AXC 355-6/25°-2-P (160) (1.1 kW) S IE3 | K19: 1248 | L19: 250 | M19: =IF(ISERROR(VLOOKUP(J19,'Germany price'!$B$1:$G$99001,6,0))," ",VLOOKUP(J19,'Germany price'!$B$1:$G$99001,6,0)) | N19: 1401 | O19: 0.58 | P19: 1 | Q19: =N19*P19*(1-O19) -> 588.42 | R19: =R18 -> 0 | S19: =Q19*(1-R19) -> 588.42 | T19: =(Q19*AE19)/AF19 -> 31.14888 | U19: =T19+S19 -> 619.56888 | V19: 0 | W19: =1.14 -> 1.14 | X19: =X18 -> 1.1235 | Y19: =Y18 -> 1 | Z19: =U19*X19*Y19*W19*(1+V19) -> 793.53763 | AA19: =AA18 -> 0.50014493 | AB19: =AC19/P19 -> 1190.4214 | AC19: =U19*X19*(1+AA19)*Y19*W19*(1+V19) -> 1190.4214 | AE19: =AE18 -> 170000 | AF19: =AF18 -> 3211396.3
A20: =VALUE(RIGHT(B20,LEN(B20)-2)) -> 17 | B20: F-17 | D20: FAF-A34-B02-01 | E20: Sweden | F20: Inline Fan | G20: Single | H20: Ambient | I20: 93097 | J20: KT 60-30-4 | K20: 745 | L20: 250 | M20: =IF(ISERROR(VLOOKUP(J20,'Germany price'!$B$1:$G$99001,6,0))," ",VLOOKUP(J20,'Germany price'!$B$1:$G$99001,6,0)) -> 1182 | N20: 1182 | O20: 0.58 | P20: 1 | Q20: =N20*P20*(1-O20) -> 496.44 | R20: =R19 -> 0 | S20: =Q20*(1-R20) -> 496.44 | T20: =(Q20*AE20)/AF20 -> 26.279783 | U20: =T20+S20 -> 522.71978 | V20: 0 | W20: =1.14 -> 1.14 | X20: =X19 -> 1.1235 | Y20: =Y19 -> 1 | Z20: =U20*X20*Y20*W20*(1+V20) -> 669.49427 | AA20: =AA19 -> 0.50014493 | AB20: =AC20/P20 -> 1004.3384 | AC20: =U20*X20*(1+AA20)*Y20*W20*(1+V20) -> 1004.3384 | AE20: =AE19 -> 170000 | AF20: =AF19 -> 3211396.3
A21: =VALUE(RIGHT(B21,LEN(B21)-2)) -> 18 | B21: F-18 | D21: FAF-A30-B01-01 | E21: Germany | F21: Axial Inline | G21: Single | H21: Ambient | I21: CAP040120001F | J21: AXC 400-6/31°-2-P (160) (2.2 kW) S IE3 C | K21: 2230 | L21: 250 | M21: =IF(ISERROR(VLOOKUP(J21,'Germany price'!$B$1:$G$99001,6,0))," ",VLOOKUP(J21,'Germany price'!$B$1:$G$99001,6,0)) | N21: 1561 | O21: 0.58 | P21: 2 | Q21: =N21*P21*(1-O21) -> 1311.24 | R21: =R20 -> 0 | S21: =Q21*(1-R21) -> 1311.24 | T21: =(Q21*AE21)/AF21 -> 69.412423 | U21: =T21+S21 -> 1380.6524 | V21: 0 | W21: =1.14 -> 1.14 | X21: =X20 -> 1.1235 | Y21: =Y20 -> 1 | Z21: =U21*X21*Y21*W21*(1+V21) -> 1768.3258 | AA21: =AA20 -> 0.50014493 | AB21: =AC21/P21 -> 1326.3725 | AC21: =U21*X21*(1+AA21)*Y21*W21*(1+V21) -> 2652.745 | AE21: =AE20 -> 170000 | AF21: =AF20 -> 3211396.3
A22: =VALUE(RIGHT(B22,LEN(B22)-2)) -> 19 | B22: F-19 | D22: FAF-A30-B01-02 | E22: Germany | F22: Centrifugal Fan | G22: Single | H22: Ambient | I22: 476764 | J22: PRF 250D4 | K22: 720 | L22: 250 | M22: =IF(ISERROR(VLOOKUP(J22,'Germany price'!$B$1:$G$99001,6,0))," ",VLOOKUP(J22,'Germany price'!$B$1:$G$99001,6,0)) -> 2020 | N22: 2020 | O22: 0.58 | P22: 1 | Q22: =N22*P22*(1-O22) -> 848.4 | R22: =R21 -> 0 | S22: =Q22*(1-R22) -> 848.4 | T22: =(Q22*AE22)/AF22 -> 44.911305 | U22: =T22+S22 -> 893.3113 | V22: 0 | W22: =1.14 -> 1.14 | X22: =X21 -> 1.1235 | Y22: =Y21 -> 1 | Z22: =U22*X22*Y22*W22*(1+V22) -> 1144.1442 | AA22: =AA21 -> 0.50014493 | AB22: =AC22/P22 -> 1716.3821 | AC22: =U22*X22*(1+AA22)*Y22*W22*(1+V22) -> 1716.3821 | AE22: =AE21 -> 170000 | AF22: =AF21 -> 3211396.3
A23: =VALUE(RIGHT(B23,LEN(B23)-2)) -> 20 | B23: F-20 | D23: FAF-A30-B01-03 | E23: Sweden | F23: Inline Fan | G23: Single | H23: Ambient | I23: 19514 | J23: K 315 L Sileo** | K23: 310 | L23: 250 | M23: =IF(ISERROR(VLOOKUP(J23,'Germany price'!$B$1:$G$99001,6,0))," ",VLOOKUP(J23,'Germany price'!$B$1:$G$99001,6,0)) -> 330 | N23: 330 | O23: 0.58 | P23: 1 | Q23: =N23*P23*(1-O23) -> 138.6 | R23: =R22 -> 0 | S23: =Q23*(1-R23) -> 138.6 | T23: =(Q23*AE23)/AF23 -> 7.3369953 | U23: =T23+S23 -> 145.937 | V23: 0 | W23: =1.14 -> 1.14 | X23: =X22 -> 1.1235 | Y23: =Y22 -> 1 | Z23: =U23*X23*Y23*W23*(1+V23) -> 186.91464 | AA23: =AA22 -> 0.50014493 | AB23: =AC23/P23 -> 280.39906 | AC23: =U23*X23*(1+AA23)*Y23*W23*(1+V23) -> 280.39906 | AE23: =AE22 -> 170000 | AF23: =AF22 -> 3211396.3
A24: =VALUE(RIGHT(B24,LEN(B24)-2)) -> 21 | B24: F-21 | D24: FAF-A30-B01-04 | E24: Sweden | F24: Inline Fan | G24: Single | H24: Ambient | I24: 19512 | J24: K 250 L sileo | K24: 235 | L24: 125 | M24: =IF(ISERROR(VLOOKUP(J24,'Germany price'!$B$1:$G$99001,6,0))," ",VLOOKUP(J24,'Germany price'!$B$1:$G$99001,6,0)) -> 223 | N24: 223 | O24: 0.58 | P24: 1 | Q24: =N24*P24*(1-O24) -> 93.66 | R24: =R23 -> 0 | S24: =Q24*(1-R24) -> 93.66 | T24: =(Q24*AE24)/AF24 -> 4.9580302 | U24: =T24+S24 -> 98.61803 | V24: 0 | W24: =1.14 -> 1.14 | X24: =X23 -> 1.1235 | Y24: =Y23 -> 1 | Z24: =U24*X24*Y24*W24*(1+V24) -> 126.30899 | AA24: =AA23 -> 0.50014493 | AB24: =AC24/P24 -> 189.48179 | AC24: =U24*X24*(1+AA24)*Y24*W24*(1+V24) -> 189.48179 | AE24: =AE23 -> 170000 | AF24: =AF23 -> 3211396.3
A25: =VALUE(RIGHT(B25,LEN(B25)-2)) -> 22 | B25: F-22 | D25: FAF-A30-B01-05 | E25: Germany | F25: Centrifugal Inline | G25: Single | H25: Ambient | I25: 235403 | J25: MUB 042 400EV Multibox | K25: 625 | L25: 250 | M25: =IF(ISERROR(VLOOKUP(J25,'Germany price'!$B$1:$G$99001,6,0))," ",VLOOKUP(J25,'Germany price'!$B$1:$G$99001,6,0)) -> 1199 | N25: 1199 | O25: 0.58 | P25: 1 | Q25: =N25*P25*(1-O25) -> 503.58 | R25: =R24 -> 0 | S25: =Q25*(1-R25) -> 503.58 | T25: =(Q25*AE25)/AF25 -> 26.65775 | U25: =T25+S25 -> 530.23775 | V25: 0 | W25: =1.14 -> 1.14 | X25: =X24 -> 1.1235 | Y25: =Y24 -> 1 | Z25: =U25*X25*Y25*W25*(1+V25) -> 679.12321 | AA25: =AA24 -> 0.50014493 | AB25: =AC25/P25 -> 1018.7832 | AC25: =U25*X25*(1+AA25)*Y25*W25*(1+V25) -> 1018.7832 | AE25: =AE24 -> 170000 | AF25: =AF24 -> 3211396.3
A26: =VALUE(RIGHT(B26,LEN(B26)-2)) -> 23 | B26: F-23 | D26: FAF-A34-B01-01 | E26: Germany | F26: Centrifugal Inline | G26: Single | H26: Ambient | I26: 276520 | J26: MUB 042 450DV Multibox | K26: 925 | L26: 250 | M26: =IF(ISERROR(VLOOKUP(J26,'Germany price'!$B$1:$G$99001,6,0))," ",VLOOKUP(J26,'Germany price'!$B$1:$G$99001,6,0)) -> 1339 | N26: 1339 | O26: 0.58 | P26: 1 | Q26: =N26*P26*(1-O26) -> 562.38 | R26: =R25 -> 0 | S26: =Q26*(1-R26) -> 562.38 | T26: =(Q26*AE26)/AF26 -> 29.770414 | U26: =T26+S26 -> 592.15041 | V26: 0 | W26: =1.14 -> 1.14 | X26: =X25 -> 1.1235 | Y26: =Y25 -> 1 | Z26: =U26*X26*Y26*W26*(1+V26) -> 758.42033 | AA26: =AA25 -> 0.50014493 | AB26: =AC26/P26 -> 1137.7404 | AC26: =U26*X26*(1+AA26)*Y26*W26*(1+V26) -> 1137.7404 | AE26: =AE25 -> 170000 | AF26: =AF25 -> 3211396.3
A27: =VALUE(RIGHT(B27,LEN(B27)-2)) -> 24 | B27: F-24 | D27: FAF-A34-B01-02 | E27: Germany | F27: Centrifugal Fan | G27: Single | H27: Ambient | I27: 476764 | J27: PRF 250D4 | K27: 545 | L27: 250 | M27: =IF(ISERROR(VLOOKUP(J27,'Germany price'!$B$1:$G$99001,6,0))," ",VLOOKUP(J27,'Germany price'!$B$1:$G$99001,6,0)) -> 2020 | N27: 2020 | O27: 0.58 | P27: 1 | Q27: =N27*P27*(1-O27) -> 848.4 | R27: =R26 -> 0 | S27: =Q27*(1-R27) -> 848.4 | T27: =(Q27*AE27)/AF27 -> 44.911305 | U27: =T27+S27 -> 893.3113 | V27: 0 | W27: =1.14 -> 1.14 | X27: =X26 -> 1.1235 | Y27: =Y26 -> 1 | Z27: =U27*X27*Y27*W27*(1+V27) -> 1144.1442 | AA27: =AA26 -> 0.50014493 | AB27: =AC27/P27 -> 1716.3821 | AC27: =U27*X27*(1+AA27)*Y27*W27*(1+V27) -> 1716.3821 | AE27: =AE26 -> 170000 | AF27: =AF26 -> 3211396.3
A28: =VALUE(RIGHT(B28,LEN(B28)-2)) -> 25 | B28: F-25 | D28: FAF-A37-B01-01 | E28: Germany | F28: Axial Inline | G28: Single | H28: Ambient | I28: CAP040120001E | J28: AXC 400-6/23°-2-P (160) (1.5 kW) S IE3 C | K28: 1780 | L28: 250 | M28: =IF(ISERROR(VLOOKUP(J28,'Germany price'!$B$1:$G$99001,6,0))," ",VLOOKUP(J28,'Germany price'!$B$1:$G$99001,6,0)) | N28: 1499 | O28: 0.58 | P28: 2 | Q28: =N28*P28*(1-O28) -> 1259.16 | R28: =R27 -> 0 | S28: =Q28*(1-R28) -> 1259.16 | T28: =(Q28*AE28)/AF28 -> 66.655491 | U28: =T28+S28 -> 1325.8155 | V28: 0 | W28: =1.14 -> 1.14 | X28: =X27 -> 1.1235 | Y28: =Y27 -> 1 | Z28: =U28*X28*Y28*W28*(1+V28) -> 1698.0912 | AA28: =AA27 -> 0.50014493 | AB28: =AC28/P28 -> 1273.6915 | AC28: =U28*X28*(1+AA28)*Y28*W28*(1+V28) -> 2547.3829 | AE28: =AE27 -> 170000 | AF28: =AF27 -> 3211396.3
A29: =VALUE(RIGHT(B29,LEN(B29)-2)) -> 26 | B29: F-26 | D29: FAF-A37-B01-02 | E29: Sweden | F29: Inline Fan | G29: Single | H29: Ambient | I29: 25365 | J29: K 160 XL sileo | K29: 155 | L29: 125 | M29: =IF(ISERROR(VLOOKUP(J29,'Germany price'!$B$1:$G$99001,6,0))," ",VLOOKUP(J29,'Germany price'!$B$1:$G$99001,6,0)) -> 171 | N29: 171 | O29: 0.58 | P29: 1 | Q29: =N29*P29*(1-O29) -> 71.82 | R29: =R28 -> 0 | S29: =Q29*(1-R29) -> 71.82 | T29: =(Q29*AE29)/AF29 -> 3.8018976 | U29: =T29+S29 -> 75.621898 | V29: 0 | W29: =1.14 -> 1.14 | X29: =X28 -> 1.1235 | Y29: =Y28 -> 1 | Z29: =U29*X29*Y29*W29*(1+V29) -> 96.85577 | AA29: =AA28 -> 0.50014493 | AB29: =AC29/P29 -> 145.29769 | AC29: =U29*X29*(1+AA29)*Y29*W29*(1+V29) -> 145.29769 | AE29: =AE28 -> 170000 | AF29: =AF28 -> 3211396.3
A30: =VALUE(RIGHT(B30,LEN(B30)-2)) -> 27 | B30: F-27 | D30: FAF-A37-B01-03 | E30: Germany | F30: Axial Inline | G30: Single | H30: Ambient | I30: CAP035120001D | J30: AXC 355-6/25°-2-P (160) (1.1 kW) S IE3 C | K30: 1250 | L30: 250 | M30: =IF(ISERROR(VLOOKUP(J30,'Germany price'!$B$1:$G$99001,6,0))," ",VLOOKUP(J30,'Germany price'!$B$1:$G$99001,6,0)) | N30: 1401 | O30: 0.58 | P30: 1 | Q30: =N30*P30*(1-O30) -> 588.42 | R30: =R29 -> 0 | S30: =Q30*(1-R30) -> 588.42 | T30: =(Q30*AE30)/AF30 -> 31.14888 | U30: =T30+S30 -> 619.56888 | V30: 0 | W30: =1.14 -> 1.14 | X30: =X29 -> 1.1235 | Y30: =Y29 -> 1 | Z30: =U30*X30*Y30*W30*(1+V30) -> 793.53763 | AA30: =AA29 -> 0.50014493 | AB30: =AC30/P30 -> 1190.4214 | AC30: =U30*X30*(1+AA30)*Y30*W30*(1+V30) -> 1190.4214 | AE30: =AE29 -> 170000 | AF30: =AF29 -> 3211396.3
A31: =VALUE(RIGHT(B31,LEN(B31)-2)) -> 28 | B31: F-28 | D31: FAF-B30-B01-02 | E31: Germany | F31: Axial Inline | G31: Single | H31: Ambient | I31: CAP071140001G | J31: AXC 710-9/20°-4-P (350) (3 kW) S IE3 C | K31: 3570 | L31: 375 | M31: =IF(ISERROR(VLOOKUP(J31,'Germany price'!$B$1:$G$99001,6,0))," ",VLOOKUP(J31,'Germany price'!$B$1:$G$99001,6,0)) | N31: 2515 | O31: 0.58 | P31: 2 | Q31: =N31*P31*(1-O31) -> 2112.6 | R31: =R30 -> 0 | S31: =Q31*(1-R31) -> 2112.6 | T31: =(Q31*AE31)/AF31 -> 111.8336 | U31: =T31+S31 -> 2224.4336 | V31: 0 | W31: =1.14 -> 1.14 | X31: =X30 -> 1.1235 | Y31: =Y30 -> 1 | Z31: =U31*X31*Y31*W31*(1+V31) -> 2849.0323 | AA31: =AA30 -> 0.50014493 | AB31: =AC31/P31 -> 2136.9807 | AC31: =U31*X31*(1+AA31)*Y31*W31*(1+V31) -> 4273.9614 | AE31: =AE30 -> 170000 | AF31: =AF30 -> 3211396.3
A32: =VALUE(RIGHT(B32,LEN(B32)-2)) -> 29 | B32: F-29 | D32: FAF-B30-B01-03 | E32: Germany | F32: Centrifugal Inline | G32: Single | H32: Ambient | I32: 235401 | J32: MUB 025 355EV Multibox | K32: 520 | L32: 125 | M32: =IF(ISERROR(VLOOKUP(J32,'Germany price'!$B$1:$G$99001,6,0))," ",VLOOKUP(J32,'Germany price'!$B$1:$G$99001,6,0)) -> 999 | N32: 999 | O32: 0.58 | P32: 1 | Q32: =N32*P32*(1-O32) -> 419.58 | R32: =R31 -> 0 | S32: =Q32*(1-R32) -> 419.58 | T32: =(Q32*AE32)/AF32 -> 22.211086 | U32: =T32+S32 -> 441.79109 | V32: 0 | W32: =1.14 -> 1.14 | X32: =X31 -> 1.1235 | Y32: =Y31 -> 1 | Z32: =U32*X32*Y32*W32*(1+V32) -> 565.8416 | AA32: =AA31 -> 0.50014493 | AB32: =AC32/P32 -> 848.84442 | AC32: =U32*X32*(1+AA32)*Y32*W32*(1+V32) -> 848.84442 | AE32: =AE31 -> 170000 | AF32: =AF31 -> 3211396.3
A33: =VALUE(RIGHT(B33,LEN(B33)-2)) -> 30 | B33: F-30 | D33: FAF-B34-B01-02 | E33: Sweden | F33: Inline Fan | G33: Single | H33: Ambient | I33: 19512 | J33: K 250 L sileo | K33: 230 | L33: 125 | M33: =IF(ISERROR(VLOOKUP(J33,'Germany price'!$B$1:$G$99001,6,0))," ",VLOOKUP(J33,'Germany price'!$B$1:$G$99001,6,0)) -> 223 | N33: 223 | O33: 0.58 | P33: 1 | Q33: =N33*P33*(1-O33) -> 93.66 | R33: =R32 -> 0 | S33: =Q33*(1-R33) -> 93.66 | T33: =(Q33*AE33)/AF33 -> 4.9580302 | U33: =T33+S33 -> 98.61803 | V33: 0 | W33: =1.14 -> 1.14 | X33: =X32 -> 1.1235 | Y33: =Y32 -> 1 | Z33: =U33*X33*Y33*W33*(1+V33) -> 126.30899 | AA33: =AA32 -> 0.50014493 | AB33: =AC33/P33 -> 189.48179 | AC33: =U33*X33*(1+AA33)*Y33*W33*(1+V33) -> 189.48179 | AE33: =AE32 -> 170000 | AF33: =AF32 -> 3211396.3
A34: =VALUE(RIGHT(B34,LEN(B34)-2)) -> 31 | B34: F-31 | D34: FAF-B34-B01-03 | E34: Germany | F34: Axial Inline | G34: Single | H34: Ambient | I34: CAP045120001F | J34: AXC 450-6/21°-2-P (200) (2.2 kW) S IE3 C | K34: 2240 | L34: 375 | M34: =IF(ISERROR(VLOOKUP(J34,'Germany price'!$B$1:$G$99001,6,0))," ",VLOOKUP(J34,'Germany price'!$B$1:$G$99001,6,0)) | N34: 1666 | O34: 0.58 | P34: 2 | Q34: =N34*P34*(1-O34) -> 1399.44 | R34: =R33 -> 0 | S34: =Q34*(1-R34) -> 1399.44 | T34: =(Q34*AE34)/AF34 -> 74.08142 | U34: =T34+S34 -> 1473.5214 | V34: 0 | W34: =1.14 -> 1.14 | X34: =X33 -> 1.1235 | Y34: =Y33 -> 1 | Z34: =U34*X34*Y34*W34*(1+V34) -> 1887.2715 | AA34: =AA33 -> 0.50014493 | AB34: =AC34/P34 -> 1415.5904 | AC34: =U34*X34*(1+AA34)*Y34*W34*(1+V34) -> 2831.1808 | AE34: =AE33 -> 170000 | AF34: =AF33 -> 3211396.3
A35: =VALUE(RIGHT(B35,LEN(B35)-2)) -> 32 | B35: F-32 | D35: FAF-B37-B01-01 | E35: Germany | F35: Axial Inline | G35: Single | H35: Ambient | I35: CAP040120001F | J35: AXC 400-6/27°-2-P (160) (2.2 kW) S IE3 | K35: 2005 | L35: 250 | M35: =IF(ISERROR(VLOOKUP(J35,'Germany price'!$B$1:$G$99001,6,0))," ",VLOOKUP(J35,'Germany price'!$B$1:$G$99001,6,0)) | N35: 1561 | O35: 0.58 | P35: 1 | Q35: =N35*P35*(1-O35) -> 655.62 | R35: =R34 -> 0 | S35: =Q35*(1-R35) -> 655.62 | T35: =(Q35*AE35)/AF35 -> 34.706211 | U35: =T35+S35 -> 690.32621 | V35: 0 | W35: =1.14 -> 1.14 | X35: =X34 -> 1.1235 | Y35: =Y34 -> 1 | Z35: =U35*X35*Y35*W35*(1+V35) -> 884.16291 | AA35: =AA34 -> 0.50014493 | AB35: =AC35/P35 -> 1326.3725 | AC35: =U35*X35*(1+AA35)*Y35*W35*(1+V35) -> 1326.3725 | AE35: =AE34 -> 170000 | AF35: =AF34 -> 3211396.3
A36: =VALUE(RIGHT(B36,LEN(B36)-2)) -> 33 | B36: F-33 | D36: FAF-B37-B01-02 | E36: Germany | F36: Axial Inline | G36: Single | H36: Ambient | I36: CAP040120001E | J36: AXC 400-6/23°-2-P (160) (1.5 kW) S IE3 C | K36: 1780 | L36: 250 | M36: =IF(ISERROR(VLOOKUP(J36,'Germany price'!$B$1:$G$99001,6,0))," ",VLOOKUP(J36,'Germany price'!$B$1:$G$99001,6,0)) | N36: 1499 | O36: 0.58 | P36: 2 | Q36: =N36*P36*(1-O36) -> 1259.16 | R36: =R35 -> 0 | S36: =Q36*(1-R36) -> 1259.16 | T36: =(Q36*AE36)/AF36 -> 66.655491 | U36: =T36+S36 -> 1325.8155 | V36: 0 | W36: =1.14 -> 1.14 | X36: =X35 -> 1.1235 | Y36: =Y35 -> 1 | Z36: =U36*X36*Y36*W36*(1+V36) -> 1698.0912 | AA36: =AA35 -> 0.50014493 | AB36: =AC36/P36 -> 1273.6915 | AC36: =U36*X36*(1+AA36)*Y36*W36*(1+V36) -> 2547.3829 | AE36: =AE35 -> 170000 | AF36: =AF35 -> 3211396.3
A37: =VALUE(RIGHT(B37,LEN(B37)-2)) -> 34 | B37: F-34 | D37: FAF-B37-B01-03 | E37: Germany | F37: Centrifugal Fan | G37: Single | H37: Ambient | I37: 334079 | J37: PRF 355D4 | K37: 1035 | L37: 250 | M37: =IF(ISERROR(VLOOKUP(J37,'Germany price'!$B$1:$G$99001,6,0))," ",VLOOKUP(J37,'Germany price'!$B$1:$G$99001,6,0)) -> 6324 | N37: 6324 | O37: 0.58 | P37: 1 | Q37: =N37*P37*(1-O37) -> 2656.08 | R37: =R36 -> 0 | S37: =Q37*(1-R37) -> 2656.08 | T37: =(Q37*AE37)/AF37 -> 140.60351 | U37: =T37+S37 -> 2796.6835 | V37: 0 | W37: =1.14 -> 1.14 | X37: =X36 -> 1.1235 | Y37: =Y36 -> 1 | Z37: =U37*X37*Y37*W37*(1+V37) -> 3581.9643 | AA37: =AA36 -> 0.50014493 | AB37: =AC37/P37 -> 5373.4656 | AC37: =U37*X37*(1+AA37)*Y37*W37*(1+V37) -> 5373.4656 | AE37: =AE36 -> 170000 | AF37: =AF36 -> 3211396.3
A38: =VALUE(RIGHT(B38,LEN(B38)-2)) -> 35 | B38: F-35 | D38: FAF-C30-B01-01 | E38: Germany | F38: Axial Inline | G38: Single | H38: Ambient | I38: CAP040120001D | J38: AXC 400-6/17°-2-P (160) (1.1 kW) S IE3 C | K38: 1400 | L38: 250 | M38: =IF(ISERROR(VLOOKUP(J38,'Germany price'!$B$1:$G$99001,6,0))," ",VLOOKUP(J38,'Germany price'!$B$1:$G$99001,6,0)) | N38: 1445 | O38: 0.58 | P38: 2 | Q38: =N38*P38*(1-O38) -> 1213.8 | R38: =R37 -> 0 | S38: =Q38*(1-R38) -> 1213.8 | T38: =(Q38*AE38)/AF38 -> 64.254293 | U38: =T38+S38 -> 1278.0543 | V38: 0 | W38: =1.14 -> 1.14 | X38: =X37 -> 1.1235 | Y38: =Y37 -> 1 | Z38: =U38*X38*Y38*W38*(1+V38) -> 1636.9192 | AA38: =AA37 -> 0.50014493 | AB38: =AC38/P38 -> 1227.808 | AC38: =U38*X38*(1+AA38)*Y38*W38*(1+V38) -> 2455.616 | AE38: =AE37 -> 170000 | AF38: =AF37 -> 3211396.3
A39: =VALUE(RIGHT(B39,LEN(B39)-2)) -> 36 | B39: F-36 | D39: FAF-C30-B01-02 | E39: Germany | F39: Axial Inline | G39: Single | H39: Ambient | I39: CAP035120001D | J39: AXC 355-6/25°-2-P (160) (1.1 kW) S IE3 | K39: 1250 | L39: 250 | M39: =IF(ISERROR(VLOOKUP(J39,'Germany price'!$B$1:$G$99001,6,0))," ",VLOOKUP(J39,'Germany price'!$B$1:$G$99001,6,0)) | N39: 1401 | O39: 0.58 | P39: 1 | Q39: =N39*P39*(1-O39) -> 588.42 | R39: =R38 -> 0 | S39: =Q39*(1-R39) -> 588.42 | T39: =(Q39*AE39)/AF39 -> 31.14888 | U39: =T39+S39 -> 619.56888 | V39: 0 | W39: =1.14 -> 1.14 | X39: =X38 -> 1.1235 | Y39: =Y38 -> 1 | Z39: =U39*X39*Y39*W39*(1+V39) -> 793.53763 | AA39: =AA38 -> 0.50014493 | AB39: =AC39/P39 -> 1190.4214 | AC39: =U39*X39*(1+AA39)*Y39*W39*(1+V39) -> 1190.4214 | AE39: =AE38 -> 170000 | AF39: =AF38 -> 3211396.3
A40: =VALUE(RIGHT(B40,LEN(B40)-2)) -> 37 | B40: F-37 | D40: FAF-C34-B01-04 | E40: Germany | F40: Axial Inline | G40: Single | H40: Ambient | I40: CAP080340001H | J40: AXC 800-6/17°-4-P (350) (4 kW) S IE3 A | K40: 4470 | L40: 375 | M40: =IF(ISERROR(VLOOKUP(J40,'Germany price'!$B$1:$G$99001,6,0))," ",VLOOKUP(J40,'Germany price'!$B$1:$G$99001,6,0)) | N40: 2721 | O40: 0.58 | P40: 2 | Q40: =N40*P40*(1-O40) -> 2285.64 | R40: =R39 -> 0 | S40: =Q40*(1-R40) -> 2285.64 | T40: =(Q40*AE40)/AF40 -> 120.99372 | U40: =T40+S40 -> 2406.6337 | V40: 0 | W40: =1.14 -> 1.14 | X40: =X39 -> 1.1235 | Y40: =Y39 -> 1 | Z40: =U40*X40*Y40*W40*(1+V40) -> 3082.3924 | AA40: =AA39 -> 0.50014493 | AB40: =AC40/P40 -> 2312.0177 | AC40: =U40*X40*(1+AA40)*Y40*W40*(1+V40) -> 4624.0354 | AE40: =AE39 -> 170000 | AF40: =AF39 -> 3211396.3
A41: =VALUE(RIGHT(B41,LEN(B41)-2)) -> 38 | B41: F-38 | D41: FAF-C35-B02-02 | E41: Germany | F41: Axial Inline | G41: Single | H41: Ambient | I41: CAP040120001E | J41: AXC 400-6/23°-2-P (160) (1.5 kW) S IE3 | K41: 2240 | L41: 250 | M41: =IF(ISERROR(VLOOKUP(J41,'Germany price'!$B$1:$G$99001,6,0))," ",VLOOKUP(J41,'Germany price'!$B$1:$G$99001,6,0)) | N41: 1499 | O41: 0.58 | P41: 2 | Q41: =N41*P41*(1-O41) -> 1259.16 | R41: =R40 -> 0 | S41: =Q41*(1-R41) -> 1259.16 | T41: =(Q41*AE41)/AF41 -> 66.655491 | U41: =T41+S41 -> 1325.8155 | V41: 0 | W41: =1.14 -> 1.14 | X41: =X40 -> 1.1235 | Y41: =Y40 -> 1 | Z41: =U41*X41*Y41*W41*(1+V41) -> 1698.0912 | AA41: =AA40 -> 0.50014493 | AB41: =AC41/P41 -> 1273.6915 | AC41: =U41*X41*(1+AA41)*Y41*W41*(1+V41) -> 2547.3829 | AE41: =AE40 -> 170000 | AF41: =AF40 -> 3211396.3
...

Sheet QUOTATION
B2: sr | C2: =COST!B3 -> SN | D2: =COST!C3 -> Location | E2: =COST!D3 -> Fan Ref. (SN) | F2: =COST!E3 -> Origin | G2: =COST!F3 -> Fan Type | H2: =COST!G3 -> Speed | I2: =COST!H3 -> Smoke Rating | J2: =COST!J3 -> Item Code (Model) | K2: =COST!K3 -> Flow l/s | L2: =COST!L3 -> ESP Pa | M2: =COST!P3 -> Qty. | N2: =COST!AB3 -> Unit Price € | O2: =COST!AC3 -> Total Price €
B3: 1 | C3: =COST!B4 -> F-01 | D3: =COST!C4 -> 0 | E3: =COST!D4 -> FAF-A29-B02-01 | F3: =COST!E4 -> Germany | G3: =COST!F4 -> Axial Inline | H3: =COST!G4 -> Single | I3: =COST!H4 -> Ambient | J3: =COST!J4 -> AXC 710-9/20°-4-P (350) (3 kW) S IE3 | K3: =COST!K4 -> 3560 | L3: =COST!L4 -> 375 | M3: =COST!P4 -> 2 | N3: =COST!AB4 -> 2136.9807 | O3: =M3*N3 -> 4273.9614
B4: 2 | C4: =COST!B5 -> F-02 | D4: =COST!C5 -> 0 | E4: =COST!D5 -> FAF-A29-B02-02 | F4: =COST!E5 -> Germany | G4: =COST!F5 -> Centrifugal Inline | H4: =COST!G5 -> Single | I4: =COST!H5 -> Ambient | J4: =COST!J5 -> MUB 042 400EV Multibox | K4: =COST!K5 -> 580 | L4: =COST!L5 -> 250 | M4: =COST!P5 -> 1 | N4: =COST!AB5 -> 1018.7832 | O4: =M4*N4 -> 1018.7832
B5: 3 | C5: =COST!B6 -> F-03 | D5: =COST!C6 -> 0 | E5: =COST!D6 -> FAF-A30-B02-01 | F5: =COST!E6 -> Sweden | G5: =COST!F6 -> Inline Fan | H5: =COST!G6 -> Single | I5: =COST!H6 -> Ambient | J5: =COST!J6 -> KT 60-30-4 | K5: =COST!K6 -> 855 | L5: =COST!L6 -> 250 | M5: =COST!P6 -> 1 | N5: =COST!AB6 -> 1004.3384 | O5: =M5*N5 -> 1004.3384
B6: 4 | C6: =COST!B7 -> F-04 | D6: =COST!C7 -> 0 | E6: =COST!D7 -> FAF-A35-B02-01 | F6: =COST!E7 -> Germany | G6: =COST!F7 -> Axial Inline | H6: =COST!G7 -> Single | I6: =COST!H7 -> Ambient | J6: =COST!J7 -> AXC 400-6/31°-2-P (160) (2.2 kW) S IE3 C | K6: =COST!K7 -> 2240 | L6: =COST!L7 -> 250 | M6: =COST!P7 -> 2 | N6: =COST!AB7 -> 1273.6915 | O6: =M6*N6 -> 2547.3829
B7: 5 | C7: =COST!B8 -> F-05 | D7: =COST!C8 -> 0 | E7: =COST!D8 -> FAF-A35-B02-02 | F7: =COST!E8 -> Germany | G7: =COST!F8 -> Centrifugal Fan | H7: =COST!G8 -> Single | I7: =COST!H8 -> Ambient | J7: =COST!J8 -> PRF 355D4 | K7: =COST!K8 -> 1125 | L7: =COST!L8 -> 250 | M7: =COST!P8 -> 1 | N7: =COST!AB8 -> 5373.4656 | O7: =M7*N7 -> 5373.4656
B8: 6 | C8: =COST!B9 -> F-06 | D8: =COST!C9 -> 0 | E8: =COST!D9 -> FAF-B30-B02-02 | F8: =COST!E9 -> Sweden | G8: =COST!F9 -> Inline Fan | H8: =COST!G9 -> Single | I8: =COST!H9 -> Ambient | J8: =COST!J9 -> K 315 L Sileo** | K8: =COST!K9 -> 340 | L8: =COST!L9 -> 125 | M8: =COST!P9 -> 1 | N8: =COST!AB9 -> 280.39906 | O8: =M8*N8 -> 280.39906
B9: 7 | C9: =COST!B10 -> F-07 | D9: =COST!C10 -> 0 | E9: =COST!D10 -> FAF-B35-B02-01 | F9: =COST!E10 -> Sweden | G9: =COST!F10 -> Inline Fan | H9: =COST!G10 -> Single | I9: =COST!H10 -> Ambient | J9: =COST!J10 -> KT 60-35-4 | K9: =COST!K10 -> 1025 | L9: =COST!L10 -> 250 | M9: =COST!P10 -> 1 | N9: =COST!AB10 -> 1226.1086 | O9: =M9*N9 -> 1226.1086
B10: 8 | C10: =COST!B11 -> F-08 | D10: =COST!C11 -> 0 | E10: =COST!D11 -> FAF-B35-B02-02 | F10: =COST!E11 -> Germany | G10: =COST!F11 -> Axial Inline | H10: =COST!G11 -> Single | I10: =COST!H11 -> Ambient | J10: =COST!J11 -> AXC 800-6/20°-4-PV (350) (4 kW) S IE3 A | K10: =COST!K11 -> 5800 | L10: =COST!L11 -> 375 | M10: =COST!P11 -> 2 | N10: =COST!AB11 -> 2753.0089 | O10: =M10*N10 -> 5506.0178
B11: 9 | C11: =COST!B12 -> F-09 | D11: =COST!C12 -> 0 | E11: =COST!D12 -> FAF-B35-B02-03 | F11: =COST!E12 -> Germany | G11: =COST!F12 -> Axial Inline | H11: =COST!G12 -> Single | I11: =COST!H12 -> Ambient | J11: =COST!J12 -> AXC 450-6/23°-2-P (200) (2.2 kW) S IE3 | K11: =COST!K12 -> 2405 | L11: =COST!L12 -> 375 | M11: =COST!P12 -> 1 | N11: =COST!AB12 -> 1415.5904 | O11: =M11*N11 -> 1415.5904
B12: 10 | C12: =COST!B13 -> F-10 | D12: =COST!C13 -> 0 | E12: =COST!D13 -> FAF-B35-B02-04 | F12: =COST!E13 -> Sweden | G12: =COST!F13 -> Inline Fan | H12: =COST!G13 -> Single | I12: =COST!H13 -> Ambient | J12: =COST!J13 -> K 315 M sileo** | K12: =COST!K13 -> 210 | L12: =COST!L13 -> 250 | M12: =COST!P13 -> 1 | N12: =COST!AB13 -> 234.51557 | O12: =M12*N12 -> 234.51557
B13: 11 | C13: =COST!B14 -> F-11 | D13: =COST!C14 -> 0 | E13: =COST!D14 -> FAF-C29-B02-01 | F13: =COST!E14 -> Sweden | G13: =COST!F14 -> Inline Fan | H13: =COST!G14 -> Single | I13: =COST!H14 -> Ambient | J13: =COST!J14 -> KT 60-35-4 | K13: =COST!K14 -> 1145 | L13: =COST!L14 -> 250 | M13: =COST!P14 -> 1 | N13: =COST!AB14 -> 1226.1086 | O13: =M13*N13 -> 1226.1086
B14: 12 | C14: =COST!B15 -> F-12 | D14: =COST!C15 -> 0 | E14: =COST!D15 -> FAF-C29-B02-02 | F14: =COST!E15 -> Sweden | G14: =COST!F15 -> Inline Fan | H14: =COST!G15 -> Single | I14: =COST!H15 -> Ambient | J14: =COST!J15 -> KT 60-30-4 | K14: =COST!K15 -> 725 | L14: =COST!L15 -> 250 | M14: =COST!P15 -> 1 | N14: =COST!AB15 -> 1004.3384 | O14: =M14*N14 -> 1004.3384
... B268: 266 | C268: =COST!B269 -> F-263 | D268: =COST!C269 -> 0 | E268: =COST!D269 -> P.FR-FAN-B01-003 | F268: =COST!E269 -> Germany | G268: =COST!F269 -> Axial Inline | H268: =COST!G269 -> Single | I268: =COST!H269 -> 300°C/2Hr | J268: =COST!J269 -> AXC 1250-8/14°-4(B)-P (500) (30 kW) S IE3 | K268: =COST!K269 -> 11041/18403 | L268: =COST!L269 -> 750 | M268: =COST!P269 -> 1 | N268: =COST!AB269 -> 10084.17 | O268: =M268*N268 -> 10084.17
C269: =COST!B270 -> F-264 | D269: =COST!C270 -> 0 | E269: =COST!D270 -> P.FR-FAN-B01-004 | F269: =COST!E270 -> Germany | G269: =COST!F270 -> Axial Inline | H269: =COST!G270 -> Single | I269: =COST!H270 -> 300°C/2Hr | J269: =COST!J270 -> AXC 1250-8/14°-4(B)-P (500) (30 kW) S IE3 | K269: =COST!K270 -> 11041/18403 | L269: =COST!L270 -> 750 | M269: =COST!P270 -> 1 | N269: =COST!AB270 -> 10084.17 | O269: =M269*N269 -> 10084.17
C270: =COST!B271 -> F-265 | D270: =COST!C271 -> 0 | E270: =COST!D271 -> P.FR-FAN-B01-005 | F270: =COST!E271 -> Germany | G270: =COST!F271 -> Axial Inline | H270: =COST!G271 -> Single | I270: =COST!H271 -> 300°C/2Hr | J270: =COST!J271 -> AXC 1000-10/23°-4(B)-PV (450) (18.5 kW) S IE3 E | K270: =COST!K271 -> 7872/13119 | L270: =COST!L271 -> 750 | M270: =COST!P271 -> 1 | N270: =COST!AB271 -> 8332.9501 | O270: =M270*N270 -> 8332.9501
C271: =COST!B272 -> F-266 | D271: =COST!C272 -> 0 | E271: =COST!D272 -> P.FR-FAN-B01-006 | F271: =COST!E272 -> Germany | G271: =COST!F272 -> Axial Inline | H271: =COST!G272 -> Single | I271: =COST!H272 -> 300°C/2Hr | J271: =COST!J272 -> AXC 1000-10/23°-4(B)-PV (450) (18.5 kW) S IE3 E | K271: =COST!K272 -> 7872/13119 | L271: =COST!L272 -> 750 | M271: =COST!P272 -> 1 | N271: =COST!AB272 -> 8332.9501 | O271: =M271*N271 -> 8332.9501
C272: =COST!B273 -> F-267 | D272: =COST!C273 -> 0 | E272: =COST!D273 -> P.FR-FAN-B01-007 | F272: =COST!E273 -> Germany | G272: =COST!F273 -> Axial Inline | H272: =COST!G273 -> Single | I272: =COST!H273 -> 300°C/2Hr | J272: =COST!J273 -> AXC 1000-10/23°-4(B)-PV (450) (18.5 kW) S IE3 E | K272: =COST!K273 -> 7872/13119 | L272: =COST!L273 -> 750 | M272: =COST!P273 -> 1 | N272: =COST!AB273 -> 8332.9501 | O272: =M272*N272 -> 8332.9501
C273: =COST!B274 -> F-268 | D273: =COST!C274 -> 0 | E273: =COST!D274 -> P.FR-FAN-B01-008 | F273: =COST!E274 -> Germany | G273: =COST!F274 -> Axial Inline | H273: =COST!G274 -> Single | I273: =COST!H274 -> 300°C/2Hr | J273: =COST!J274 -> AXC 1000-10/23°-4(B)-PV (450) (18.5 kW) S IE3 E | K273: =COST!K274 -> 7872/13119 | L273: =COST!L274 -> 750 | M273: =COST!P274 -> 1 | N273: =COST!AB274 -> 8332.9501 | O273: =M273*N273 -> 8332.9501
C274: =COST!B275 -> F-269 | D274: =COST!C275 -> 0 | E274: =COST!D275 -> P.FR-FAN-B01-009 | F274: =COST!E275 -> Germany | G274: =COST!F275 -> Axial Inline | H274: =COST!G275 -> Single | I274: =COST!H275 -> 300°C/2Hr | J274: =COST!J275 -> AXC 1250-8/15°-4(B)-P (500) (30 kW) S IE3 E | K274: =COST!K275 -> 12272/20453 | L274: =COST!L275 -> 650 | M274: =COST!P275 -> 1 | N274: =COST!AB275 -> 10084.17 | O274: =M274*N274 -> 10084.17
C275: =COST!B276 -> F-270 | D275: =COST!C276 -> 0 | E275: =COST!D276 -> P.FR-FAN-B01-010 | F275: =COST!E276 -> Germany | G275: =COST!F276 -> Axial Inline | H275: =COST!G276 -> Single | I275: =COST!H276 -> 300°C/2Hr | J275: =COST!J276 -> AXC 1250-8/15°-4(B)-P (500) (30 kW) S IE3 E | K275: =COST!K276 -> 12272/20453 | L275: =COST!L276 -> 650 | M275: =COST!P276 -> 1 | N275: =COST!AB276 -> 10084.17 | O275: =M275*N275 -> 10084.17
C276: =COST!B277 -> F-271 | D276: =COST!C277 -> 0 | E276: =COST!D277 -> P.FR-FAN-B01-011 | F276: =COST!E277 -> Germany | G276: =COST!F277 -> Axial Inline | H276: =COST!G277 -> Single | I276: =COST!H277 -> 300°C/2Hr | J276: =COST!J277 -> AXC 1250-8/15°-4(B)-P (500) (30 kW) S IE3 E | K276: =COST!K277 -> 12272/20453 | L276: =COST!L277 -> 650 | M276: =COST!P277 -> 1 | N276: =COST!AB277 -> 10084.17 | O276: =M276*N276 -> 10084.17
C277: =COST!B278 -> F-272 | D277: =COST!C278 -> 0 | E277: =COST!D278 -> P.FR-FAN-B02-001 | F277: =COST!E278 -> Germany | G277: =COST!F278 -> Axial Inline | H277: =COST!G278 -> Single | I277: =COST!H278 -> 300°C/2Hr | J277: =COST!J278 -> AXC 1000-10/32°-4(B)-PV (450) (30 kW) S IE3 E | K277: =COST!K278 -> 10028/16713 | L277: =COST!L278 -> 800 | M277: =COST!P278 -> 1 | N277: =COST!AB278 -> 9842.8566 | O277: =M277*N277 -> 9842.8566
C278: =COST!B279 -> F-273 | D278: =COST!C279 -> 0 | E278: =COST!D279 -> P.FR-FAN-B02-002 | F278: =COST!E279 -> Germany | G278: =COST!F279 -> Axial Inline | H278: =COST!G279 -> Single | I278: =COST!H279 -> 300°C/2Hr | J278: =COST!J279 -> AXC 1000-10/32°-4(B)-PV (450) (30 kW) S IE3 E | K278: =COST!K279 -> 10028/16713 | L278: =COST!L279 -> 800 | M278: =COST!P279 -> 1 | N278: =COST!AB279 -> 9842.8566 | O278: =M278*N278 -> 9842.8566
C279: =COST!B280 -> F-274 | D279: =COST!C280 -> 0 | E279: =COST!D280 -> P.FR-FAN-B02-003 | F279: =COST!E280 -> Germany | G279: =COST!F280 -> Axial Inline | H279: =COST!G280 -> Single | I279: =COST!H280 -> 300°C/2Hr | J279: =COST!J280 -> AXC 1000-10/32°-4(B)-PV (450) (30 kW) S IE3 E | K279: =COST!K280 -> 10028/16713 | L279: =COST!L280 -> 800 | M279: =COST!P280 -> 1 | N279: =COST!AB280 -> 9842.8566 | O279: =M279*N279 -> 9842.8566
C280: =COST!B281 -> F-275 | D280: =COST!C281 -> 0 | E280: =COST!D281 -> P.FR-FAN-B02-004 | F280: =COST!E281 -> Germany | G280: =COST!F281 -> Axial Inline | H280: =COST!G281 -> Single | I280: =COST!H281 -> 300°C/2Hr | J280: =COST!J281 -> AXC 1000-10/32°-4(B)-PV (450) (30 kW) S IE3 E | K280: =COST!K281 -> 10028/16713 | L280: =COST!L281 -> 800 | M280: =COST!P281 -> 1 | N280: =COST!AB281 -> 9842.8566 | O280: =M280*N280 -> 9842.8566
... C748: =COST!B749 -> F-746 | D748: =COST!C749 -> 0 | E748: =COST!D749 -> 0 | F748: =COST!E749 -> 0 | G748: =COST!F749 -> 0 | H748: =COST!G749 -> 0 | I748: =COST!H749 -> 0 | J748: =COST!J749 -> 0 | K748: =COST!K749 -> 0 | L748: =COST!L749 -> 0 | M748: =COST!P749 -> 0.0001 | N748: =COST!AB749 -> 2.0230812e-07 | O748: =M748*N748 -> 2.0230812e-11
B749: 267 | C749: =COST!B750 -> F-747 | D749: =COST!C750 -> 0 | E749: =COST!D750 -> 0 | F749: =COST!E750 -> 0 | G749: =COST!F750 -> 0 | H749: =COST!G750 -> 0 | I749: =COST!H750 -> 0 | J749: =COST!J750 -> 0 | K749: =COST!K750 -> 0 | L749: =COST!L750 -> 0 | M749: =COST!P750 -> 0.0001 | N749: =COST!AB750 -> 2.0230812e-07 | O749: =M749*N749 -> 2.0230812e-11
B750: 268 | C750: =COST!B751 -> F-748 | D750: =COST!C751 -> 0 | E750: =COST!D751 -> 0 | F750: =COST!E751 -> 0 | G750: =COST!F751 -> 0 | H750: =COST!G751 -> 0 | I750: =COST!H751 -> 0 | J750: =COST!J751 -> 0 | K750: =COST!K751 -> 0 | L750: =COST!L751 -> 0 | M750: =COST!P751 -> 0.0001 | N750: =COST!AB751 -> 2.0230812e-07 | O750: =M750*N750 -> 2.0230812e-11
B751: 269 | C751: =COST!B752 -> F-749 | D751: =COST!C752 -> 0 | E751: =COST!D752 -> 0 | F751: =COST!E752 -> 0 | G751: =COST!F752 -> 0 | H751: =COST!G752 -> 0 | I751: =COST!H752 -> 0 | J751: =COST!J752 -> 0 | K751: =COST!K752 -> 0 | L751: =COST!L752 -> 0 | M751: =COST!P752 -> 0.0001 | N751: =COST!AB752 -> 2.0230812e-07 | O751: =M751*N751 -> 2.0230812e-11
B752: 270 | C752: =COST!B753 -> F-750 | D752: =COST!C753 -> 0 | E752: =COST!D753 -> 0 | F752: =COST!E753 -> 0 | G752: =COST!F753 -> 0 | H752: =COST!G753 -> 0 | I752: =COST!H753 -> 0 | J752: =COST!J753 -> 0 | K752: =COST!K753 -> 0 | L752: =COST!L753 -> 0 | M752: =COST!P753 -> 0.0001 | N752: =COST!AB753 -> 2.0230812e-07 | O752: =M752*N752 -> 2.0230812e-11
B753: 271 | C753: =COST!B754 -> F-751 | D753: =COST!C754 -> 0 | E753: =COST!D754 -> 0 | F753: =COST!E754 -> 0 | G753: =COST!F754 -> 0 | H753: =COST!G754 -> 0 | I753: =COST!H754 -> 0 | J753: =COST!J754 -> 0 | K753: =COST!K754 -> 0 | L753: =COST!L754 -> 0 | M753: =COST!P754 -> 0.0001 | N753: =COST!AB754 -> 2.0230812e-07 | O753: =M753*N753 -> 2.0230812e-11
B754: 272 | C754: =COST!B755 -> F-752 | D754: =COST!C755 -> 0 | E754: =COST!D755 -> 0 | F754: =COST!E755 -> 0 | G754: =COST!F755 -> 0 | H754: =COST!G755 -> 0 | I754: =COST!H755 -> 0 | J754: =COST!J755 -> 0 | K754: =COST!K755 -> 0 | L754: =COST!L755 -> 0 | M754: =COST!P755 -> 0.0001 | N754: =COST!AB755 -> 2.0230812e-07 | O754: =M754*N754 -> 2.0230812e-11
B755: 273 | C755: =COST!B756 -> F-753 | D755: =COST!C756 -> 0 | E755: =COST!D756 -> 0 | F755: =COST!E756 -> 0 | G755: =COST!F756 -> 0 | H755: =COST!G756 -> 0 | I755: =COST!H756 -> 0 | J755: =COST!J756 -> 0 | K755: =COST!K756 -> 0 | L755: =COST!L756 -> 0 | M755: =COST!P756 -> 0.0001 | N755: =COST!AB756 -> 2.0230812e-07 | O755: =M755*N755 -> 2.0230812e-11
B756: 274 | C756: =COST!B757 -> F-754 | D756: =COST!C757 -> 0 | E756: =COST!D757 -> 0 | F756: =COST!E757 -> 0 | G756: =COST!F757 -> 0 | H756: =COST!G757 -> 0 | I756: =COST!H757 -> 0 | J756: =COST!J757 -> 0 | K756: =COST!K757 -> 0 | L756: =COST!L757 -> 0 | M756: =COST!P757 -> 0.0001 | N756: =COST!AB757 -> 2.0230812e-07 | O756: =M756*N756 -> 2.0230812e-11
B757: 275 | C757: =COST!B758 -> F-755 | D757: =COST!C758 -> 0 | E757: =COST!D758 -> 0 | F757: =COST!E758 -> 0 | G757: =COST!F758 -> 0 | H757: =COST!G758 -> 0 | I757: =COST!H758 -> 0 | J757: =COST!J758 -> 0 | K757: =COST!K758 -> 0 | L757: =COST!L758 -> 0 | M757: =COST!P758 -> 0.0001 | N757: =COST!AB758 -> 2.0230812e-07 | O757: =M757*N757 -> 2.0230812e-11
B758: 276 | C758: =COST!B759 -> F-756 | D758: =COST!C759 -> 0 | E758: =COST!D759 -> 0 | F758: =COST!E759 -> 0 | G758: =COST!F759 -> 0 | H758: =COST!G759 -> 0 | I758: =COST!H759 -> 0 | J758: =COST!J759 -> 0 | K758: =COST!K759 -> 0 | L758: =COST!L759 -> 0 | M758: =COST!P759 -> 0.0001 | N758: =COST!AB759 -> 2.0230812e-07 | O758: =M758*N758 -> 2.0230812e-11
B759: 277 | C759: =COST!B760 -> F-757 | D759: =COST!C760 -> 0 | E759: =COST!D760 -> 0 | F759: =COST!E760 -> 0 | G759: =COST!F760 -> 0 | H759: =COST!G760 -> 0 | I759: =COST!H760 -> 0 | J759: =COST!J760 -> 0 | K759: =COST!K760 -> 0 | L759: =COST!L760 -> 0 | M759: =COST!P760 -> 0.0001 | N759: =COST!AB760 -> 2.0230812e-07 | O759: =M759*N759 -> 2.0230812e-11
B760: 278 | C760: =COST!B761 -> F-758 | D760: =COST!C761 -> 0 | E760: =COST!D761 -> 0 | F760: =COST!E761 -> 0 | G760: =COST!F761 -> 0 | H760: =COST!G761 -> 0 | I760: =COST!H761 -> 0 | J760: =COST!J761 -> 0 | K760: =COST!K761 -> 0 | L760: =COST!L761 -> 0 | M760: =COST!P761 -> 0.0001 | N760: =COST!AB761 -> 2.0230812e-07 | O760: =M760*N760 -> 2.0230812e-11
... B785: 303 | C785: =COST!B786 -> F-783 | D785: =COST!C786 -> 0 | E785: =COST!D786 -> 0 | F785: =COST!E786 -> 0 | G785: =COST!F786 -> 0 | H785: =COST!G786 -> 0 | I785: =COST!H786 -> 0 | J785: =COST!J786 -> 0 | K785: =COST!K786 -> 0 | L785: =COST!L786 -> 0 | M785: =COST!P786 -> 0.0001 | N785: =COST!AB786 -> 2.0230812e-07 | O785: =M785*N785 -> 2.0230812e-11
...

Sheet SUPPLIER
A9: SN | B9: Reference | C9: Origin | D9: Fan Type | E9: Speed | F9: Smoke Rating | G9: Article No. | H9: Model | I9: =COST!K3 -> Flow l/s | J9: =COST!L3 -> ESP Pa | K9: Qty.
A10: =COST!B4 -> F-01 | B10: =COST!D4 -> FAF-A29-B02-01 | C10: =COST!E4 -> Germany | D10: =COST!F4 -> Axial Inline | E10: =COST!G4 -> Single | F10: =COST!H4 -> Ambient | G10: =COST!I4 -> CAP071140001G | H10: =COST!J4 -> AXC 710-9/20°-4-P (350) (3 kW) S IE3 | I10: =COST!K4 -> 3560 | J10: =COST!L4 -> 375 | K10: =COST!P4 -> 2
A11: =COST!B5 -> F-02 | B11: =COST!D5 -> FAF-A29-B02-02 | C11: =COST!E5 -> Germany | D11: =COST!F5 -> Centrifugal Inline | E11: =COST!G5 -> Single | F11: =COST!H5 -> Ambient | G11: =COST!I5 -> 235403 | H11: =COST!J5 -> MUB 042 400EV Multibox | I11: =COST!K5 -> 580 | J11: =COST!L5 -> 250 | K11: =COST!P5 -> 1
A12: =COST!B6 -> F-03 | B12: =COST!D6 -> FAF-A30-B02-01 | C12: =COST!E6 -> Sweden | D12: =COST!F6 -> Inline Fan | E12: =COST!G6 -> Single | F12: =COST!H6 -> Ambient | G12: =COST!I6 -> 93097 | H12: =COST!J6 -> KT 60-30-4 | I12: =COST!K6 -> 855 | J12: =COST!L6 -> 250 | K12: =COST!P6 -> 1
A13: =COST!B7 -> F-04 | B13: =COST!D7 -> FAF-A35-B02-01 | C13: =COST!E7 -> Germany | D13: =COST!F7 -> Axial Inline | E13: =COST!G7 -> Single | F13: =COST!H7 -> Ambient | G13: =COST!I7 -> CAP040120001F | H13: =COST!J7 -> AXC 400-6/31°-2-P (160) (2.2 kW) S IE3 C | I13: =COST!K7 -> 2240 | J13: =COST!L7 -> 250 | K13: =COST!P7 -> 2
A14: =COST!B8 -> F-05 | B14: =COST!D8 -> FAF-A35-B02-02 | C14: =COST!E8 -> Germany | D14: =COST!F8 -> Centrifugal Fan | E14: =COST!G8 -> Single | F14: =COST!H8 -> Ambient | G14: =COST!I8 -> 334079 | H14: =COST!J8 -> PRF 355D4 | I14: =COST!K8 -> 1125 | J14: =COST!L8 -> 250 | K14: =COST!P8 -> 1
A15: =COST!B9 -> F-06 | B15: =COST!D9 -> FAF-B30-B02-02 | C15: =COST!E9 -> Sweden | D15: =COST!F9 -> Inline Fan | E15: =COST!G9 -> Single | F15: =COST!H9 -> Ambient | G15: =COST!I9 -> 19514 | H15: =COST!J9 -> K 315 L Sileo** | I15: =COST!K9 -> 340 | J15: =COST!L9 -> 125 | K15: =COST!P9 -> 1
A16: =COST!B10 -> F-07 | B16: =COST!D10 -> FAF-B35-B02-01 | C16: =COST!E10 -> Sweden | D16: =COST!F10 -> Inline Fan | E16: =COST!G10 -> Single | F16: =COST!H10 -> Ambient | G16: =COST!I10 -> 93098 | H16: =COST!J10 -> KT 60-35-4 | I16: =COST!K10 -> 1025 | J16: =COST!L10 -> 250 | K16: =COST!P10 -> 1
A17: =COST!B11 -> F-08 | B17: =COST!D11 -> FAF-B35-B02-02 | C17: =COST!E11 -> Germany | D17: =COST!F11 -> Axial Inline | E17: =COST!G11 -> Single | F17: =COST!H11 -> Ambient | G17: =COST!I11 -> CAPV080340001H | H17: =COST!J11 -> AXC 800-6/20°-4-PV (350) (4 kW) S IE3 A | I17: =COST!K11 -> 5800 | J17: =COST!L11 -> 375 | K17: =COST!P11 -> 2
A18: =COST!B12 -> F-09 | B18: =COST!D12 -> FAF-B35-B02-03 | C18: =COST!E12 -> Germany | D18: =COST!F12 -> Axial Inline | E18: =COST!G12 -> Single | F18: =COST!H12 -> Ambient | G18: =COST!I12 -> CAP045120001F | H18: =COST!J12 -> AXC 450-6/23°-2-P (200) (2.2 kW) S IE3 | I18: =COST!K12 -> 2405 | J18: =COST!L12 -> 375 | K18: =COST!P12 -> 1
A19: =COST!B13 -> F-10 | B19: =COST!D13 -> FAF-B35-B02-04 | C19: =COST!E13 -> Sweden | D19: =COST!F13 -> Inline Fan | E19: =COST!G13 -> Single | F19: =COST!H13 -> Ambient | G19: =COST!I13 -> 27758 | H19: =COST!J13 -> K 315 M sileo** | I19: =COST!K13 -> 210 | J19: =COST!L13 -> 250 | K19: =COST!P13 -> 1
A20: =COST!B14 -> F-11 | B20: =COST!D14 -> FAF-C29-B02-01 | C20: =COST!E14 -> Sweden | D20: =COST!F14 -> Inline Fan | E20: =COST!G14 -> Single | F20: =COST!H14 -> Ambient | G20: =COST!I14 -> 93098 | H20: =COST!J14 -> KT 60-35-4 | I20: =COST!K14 -> 1145 | J20: =COST!L14 -> 250 | K20: =COST!P14 -> 1
A21: =COST!B15 -> F-12 | B21: =COST!D15 -> FAF-C29-B02-02 | C21: =COST!E15 -> Sweden | D21: =COST!F15 -> Inline Fan | E21: =COST!G15 -> Single | F21: =COST!H15 -> Ambient | G21: =COST!I15 -> 93097 | H21: =COST!J15 -> KT 60-30-4 | I21: =COST!K15 -> 725 | J21: =COST!L15 -> 250 | K21: =COST!P15 -> 1
... A53: =COST!B47 -> F-44 | B53: =COST!D47 -> EXF-A30-B02-03 | C53: =COST!E47 -> Sweden | D53: =COST!F47 -> Inline Fan | E53: =COST!G47 -> Single | F53: =COST!H47 -> Ambient | G53: =COST!I47 -> 19510 | H53: =COST!J47 -> K 200 L sileo | I53: =COST!K47 -> 195 | J53: =COST!L47 -> 125 | K53: =COST!P47 -> 1
A54: =COST!B168 -> F-164 | B54: =COST!D168 -> PR.FAN-C29-RF-01 | C54: =COST!E168 -> Germany | D54: =COST!F168 -> Axial Inline | E54: =COST!G168 -> Single | F54: =COST!H168 -> Ambient | G54: =COST!I168 -> CAPV080140001J | H54: =COST!J168 -> AXC 800-9/25°-4-PV (350) (7.5 kW) S IE3 A | I54: =COST!K168 -> 7255 | J54: =COST!L168 -> 500 | K54: =COST!P168 -> 1
A55: =COST!B169 -> F-165 | B55: =COST!D169 -> PR.FAN-A29-RF-01 | C55: =COST!E169 -> Germany | D55: =COST!F169 -> Axial Inline | E55: =COST!G169 -> Single | F55: =COST!H169 -> Ambient | G55: =COST!I169 -> CAPV080140001J | H55: =COST!J169 -> AXC 800-9/25°-4-PV (350) (7.5 kW) S IE3 A | I55: =COST!K169 -> 7260 | J55: =COST!L169 -> 500 | K55: =COST!P169 -> 1
A56: =COST!B170 -> F-166 | B56: =COST!D170 -> PR.FAN-A29-L05-01 | C56: =COST!E170 -> Germany | D56: =COST!F170 -> Axial Inline | E56: =COST!G170 -> Single | F56: =COST!H170 -> Ambient | G56: =COST!I170 -> CAP090140001J | H56: =COST!J170 -> AXC 900-10/18°-4-P (450) (7.5 kW) S IE3 A | I56: =COST!K170 -> 7465 | J56: =COST!L170 -> 500 | K56: =COST!P170 -> 1
A57: =COST!B171 -> F-167 | B57: =COST!D171 -> PR.FAN-C29-L05-01 | C57: =COST!E171 -> Germany | D57: =COST!F171 -> Axial Inline | E57: =COST!G171 -> Single | F57: =COST!H171 -> Ambient | G57: =COST!I171 -> CAP090140001J | H57: =COST!J171 -> AXC 900-10/18°-4-P (450) (7.5 kW) S IE3 A | I57: =COST!K171 -> 7460 | J57: =COST!L171 -> 500 | K57: =COST!P171 -> 1
A58: =COST!B172 -> F-168 | B58: =COST!D172 -> PR.FAN-B29-RF-01 | C58: =COST!E172 -> Germany | D58: =COST!F172 -> Axial Inline | E58: =COST!G172 -> Single | F58: =COST!H172 -> Ambient | G58: =COST!I172 -> CAP090140001J | H58: =COST!J172 -> AXC 900-10/17°-4-P (450) (7.5 kW) S IE3 A | I58: =COST!K172 -> 6915 | J58: =COST!L172 -> 500 | K58: =COST!P172 -> 1
A59: =COST!B173 -> F-169 | B59: =COST!D173 -> EXF-A29-GF-01 | C59: =COST!E173 -> Germany | D59: =COST!F173 -> Wall Mounted | E59: =COST!G173 -> Single | F59: =COST!H173 -> Ambient | G59: =COST!I173 -> 246889 | H59: =COST!J173 -> AW 350E4 sileo Axial fan | I59: =COST!K173 -> 670 | J59: =COST!L173 -> - | K59: =COST!P173 -> 1
A60: =COST!B174 -> F-170 | B60: =COST!D174 -> EXF-A29-RF-01 | C60: =COST!E174 -> Sweden | D60: =COST!F174 -> Inline Fan | E60: =COST!G174 -> Single | F60: =COST!H174 -> Ambient | G60: =COST!I174 -> 27758 | H60: =COST!J174 -> K 315 M sileo** | I60: =COST!K174 -> 240 | J60: =COST!L174 -> 150 | K60: =COST!P174 -> 1
A61: =COST!B175 -> F-171 | B61: =COST!D175 -> EXF-A29-L05-01 | C61: =COST!E175 -> Germany | D61: =COST!F175 -> Centrifugal Inline | E61: =COST!G175 -> Single | F61: =COST!H175 -> Ambient | G61: =COST!I175 -> 235403 | H61: =COST!J175 -> MUB 042 400EV Multibox | I61: =COST!K175 -> 655 | J61: =COST!L175 -> 200 | K61: =COST!P175 -> 1
A62: =COST!B176 -> F-172 | B62: =COST!D176 -> EXF-B29-RF-01 | C62: =COST!E176 -> Sweden | D62: =COST!F176 -> Inline Fan | E62: =COST!G176 -> Single | F62: =COST!H176 -> Ambient | G62: =COST!I176 -> 1487 | H62: =COST!J176 -> KT 50-25-4 | I62: =COST!K176 -> 410 | J62: =COST!L176 -> 150 | K62: =COST!P176 -> 1
A63: =COST!B177 -> F-173 | B63: =COST!D177 -> EXF-C29-RF-01 | C63: =COST!E177 -> Sweden | D63: =COST!F177 -> Inline Fan | E63: =COST!G177 -> Single | F63: =COST!H177 -> Ambient | G63: =COST!I177 -> 27758 | H63: =COST!J177 -> K 315 M sileo** | I63: =COST!K177 -> 265 | J63: =COST!L177 -> 150 | K63: =COST!P177 -> 1
A64: =COST!B178 -> F-174 | B64: =COST!D178 -> EXF-C29-L05-01 | C64: =COST!E178 -> Sweden | D64: =COST!F178 -> Inline Fan | E64: =COST!G178 -> Single | F64: =COST!H178 -> Ambient | G64: =COST!I178 -> 19512 | H64: =COST!J178 -> K 250 L sileo | I64: =COST!K178 -> 220 | J64: =COST!L178 -> 150 | K64: =COST!P178 -> 1
A65: =COST!B179 -> F-175 | B65: =COST!D179 -> EXF-A29-GR-02 | C65: =COST!E179 -> Germany | D65: =COST!F179 -> Wall Mounted | E65: =COST!G179 -> Single | F65: =COST!H179 -> Ambient | G65: =COST!I179 -> 37411 | H65: =COST!J179 -> AW 450E4 sileo Axial fan | I65: =COST!K179 -> 1185 | J65: =COST!L179 -> - | K65: =COST!P179 -> 1
... A67: =COST!B181 -> F-177 | B67: =COST!D181 -> FAF-A29-GR-01 | C67: =COST!E181 -> Germany | D67: =COST!F181 -> Wall Mounted | E67: =COST!G181 -> Single | F67: =COST!H181 -> Ambient | G67: =COST!I181 -> 37411 | H67: =COST!J181 -> AW 450E4 sileo Axial fan | I67: =COST!K181 -> 1250 | J67: =COST!L181 -> - | K67: =COST!P181 -> 1
A68: =COST!B866 -> F-863 | B68: =COST!D866 -> 0 | C68: =COST!E866 -> 0 | D68: =COST!F866 -> 0 | E68: =COST!G866 -> 0 | F68: =COST!H866 -> 0 | G68: =COST!I866 -> 0 | H68: =COST!J866 -> 0 | I68: =COST!K866 -> 0 | J68: =COST!L866 -> 0 | K68: =COST!P866 -> 0.0001
A69: =COST!B867 -> F-864 | B69: =COST!D867 -> 0 | C69: =COST!E867 -> 0 | D69: =COST!F867 -> 0 | E69: =COST!G867 -> 0 | F69: =COST!H867 -> 0 | G69: =COST!I867 -> 0 | H69: =COST!J867 -> 0 | I69: =COST!K867 -> 0 | J69: =COST!L867 -> 0 | K69: =COST!P867 -> 0.0001
A70: =COST!B868 -> F-865 | B70: =COST!D868 -> 0 | C70: =COST!E868 -> 0 | D70: =COST!F868 -> 0 | E70: =COST!G868 -> 0 | F70: =COST!H868 -> 0 | G70: =COST!I868 -> 0 | H70: =COST!J868 -> 0 | I70: =COST!K868 -> 0 | J70: =COST!L868 -> 0 | K70: =COST!P868 -> 0.0001
A71: =COST!B869 -> F-866 | B71: =COST!D869 -> 0 | C71: =COST!E869 -> 0 | D71: =COST!F869 -> 0 | E71: =COST!G869 -> 0 | F71: =COST!H869 -> 0 | G71: =COST!I869 -> 0 | H71: =COST!J869 -> 0 | I71: =COST!K869 -> 0 | J71: =COST!L869 -> 0 | K71: =COST!P869 -> 0.0001
A72: =COST!B870 -> F-867 | B72: =COST!D870 -> 0 | C72: =COST!E870 -> 0 | D72: =COST!F870 -> 0 | E72: =COST!G870 -> 0 | F72: =COST!H870 -> 0 | G72: =COST!I870 -> 0 | H72: =COST!J870 -> 0 | I72: =COST!K870 -> 0 | J72: =COST!L870 -> 0 | K72: =COST!P870 -> 0.0001
A73: =COST!B871 -> F-868 | B73: =COST!D871 -> 0 | C73: =COST!E871 -> 0 | D73: =COST!F871 -> 0 | E73: =COST!G871 -> 0 | F73: =COST!H871 -> 0 | G73: =COST!I871 -> 0 | H73: =COST!J871 -> 0 | I73: =COST!K871 -> 0 | J73: =COST!L871 -> 0 | K73: =COST!P871 -> 0.0001
A74: =COST!B872 -> F-869 | B74: =COST!D872 -> 0 | C74: =COST!E872 -> 0 | D74: =COST!F872 -> 0 | E74: =COST!G872 -> 0 | F74: =COST!H872 -> 0 | G74: =COST!I872 -> 0 | H74: =COST!J872 -> 0 | I74: =COST!K872 -> 0 | J74: =COST!L872 -> 0 | K74: =COST!P872 -> 0.0001
A75: =COST!B873 -> F-870 | B75: =COST!D873 -> 0 | C75: =COST!E873 -> 0 | D75: =COST!F873 -> 0 | E75: =COST!G873 -> 0 | F75: =COST!H873 -> 0 | G75: =COST!I873 -> 0 | H75: =COST!J873 -> 0 | I75: =COST!K873 -> 0 | J75: =COST!L873 -> 0 | K75: =COST!P873 -> 0.0001
A76: =COST!B874 -> F-871 | B76: =COST!D874 -> 0 | C76: =COST!E874 -> 0 | D76: =COST!F874 -> 0 | E76: =COST!G874 -> 0 | F76: =COST!H874 -> 0 | G76: =COST!I874 -> 0 | H76: =COST!J874 -> 0 | I76: =COST!K874 -> 0 | J76: =COST!L874 -> 0 | K76: =COST!P874 -> 0.0001
A77: =COST!B875 -> F-872 | B77: =COST!D875 -> 0 | C77: =COST!E875 -> 0 | D77: =COST!F875 -> 0 | E77: =COST!G875 -> 0 | F77: =COST!H875 -> 0 | G77: =COST!I875 -> 0 | H77: =COST!J875 -> 0 | I77: =COST!K875 -> 0 | J77: =COST!L875 -> 0 | K77: =COST!P875 -> 0.0001
A78: =COST!B876 -> F-873 | B78: =COST!D876 -> 0 | C78: =COST!E876 -> 0 | D78: =COST!F876 -> 0 | E78: =COST!G876 -> 0 | F78: =COST!H876 -> 0 | G78: =COST!I876 -> 0 | H78: =COST!J876 -> 0 | I78: =COST!K876 -> 0 | J78: =COST!L876 -> 0 | K78: =COST!P876 -> 0.0001
A79: =COST!B877 -> F-874 | B79: =COST!D877 -> 0 | C79: =COST!E877 -> 0 | D79: =COST!F877 -> 0 | E79: =COST!G877 -> 0 | F79: =COST!H877 -> 0 | G79: =COST!I877 -> 0 | H79: =COST!J877 -> 0 | I79: =COST!K877 -> 0 | J79: =COST!L877 -> 0 | K79: =COST!P877 -> 0.0001
... A84: =COST!B882 -> F-879 | B84: =COST!D882 -> 0 | C84: =COST!E882 -> 0 | D84: =COST!F882 -> 0 | E84: =COST!G882 -> 0 | F84: =COST!H882 -> 0 | G84: =COST!I882 -> 0 | H84: =COST!J882 -> 0 | I84: =COST!K882 -> 0 | J84: =COST!L882 -> 0 | K84: =COST!P882 -> 0.0001
...

Sheet Germany price
A1: Item no | B1: Item name | C1: Business area descr | D1: Product group descr | E1: Item group descr | F1: Family name | G1: Sales price | H1: Price list Currency
A2: 1001 | B2: K 100 M sileo | D2: 201 Circular duct fans | E2: 20101 Circular duct fans | F2: K | G2: 130 | H2: EUR
A3: 1002 | B3: K 125 M sileo | D3: 201 Circular duct fans | E3: 20101 Circular duct fans | F3: K | G3: 131 | H3: EUR
A4: 19510 | B4: K 200 L sileo | D4: 201 Circular duct fans | E4: 20101 Circular duct fans | F4: K | G4: 208 | H4: EUR
A5: 19512 | B5: K 250 L sileo | D5: 201 Circular duct fans | E5: 20101 Circular duct fans | F5: K | G5: 223 | H5: EUR
A6: 19514 | B6: K 315 L Sileo** | D6: 201 Circular duct fans | E6: 20101 Circular duct fans | F6: K | G6: 330 | H6: EUR
A7: 25360 | B7: K 100 XL sileo | D7: 201 Circular duct fans | E7: 20101 Circular duct fans | F7: K | G7: 140 | H7: EUR
A8: 25361 | B8: K 125 XL sileo | D8: 201 Circular duct fans | E8: 20101 Circular duct fans | F8: K | G8: 141 | H8: EUR
A9: 25362 | B9: K 150 M Sileo | D9: 201 Circular duct fans | E9: 20101 Circular duct fans | F9: K | G9: 145 | H9: EUR
A10: 25363 | B10: K 150 XL sileo | D10: 201 Circular duct fans | E10: 20101 Circular duct fans | F10: K | G10: 171 | H10: EUR
